Workbook

Sheet BSE_500_LIVE
A1: BSE Code | B1: Company Name | C1: BSE_CMP_Official | D1: BSE_52W_High_Official | E1: BSE_52W_Low_Official | F1: Last Refreshed | G1: Source URL
A2: 500008 | B2: Amara Raja Energy & Mobility Ltd | G2: https://www.bseindia.com/stock-share-price/Amara-Raja-Energy-&-Mobility-Ltd/500008/
A3: 500034 | B3: Bajaj Finance Ltd | G3: https://www.bseindia.com/stock-share-price/Bajaj-Finance-Ltd/500034/
A4: 500055 | B4: Bombay Dyeing | G4: https://www.bseindia.com/stock-share-price/Bombay-Dyeing/500055/
A5: 500059 | B5: Birla Power Solutions Ltd | G5: https://www.bseindia.com/stock-share-price/Birla-Power-Solutions-Ltd/500059/
A6: 500089 | B6: Dichloromethane | G6: https://www.bseindia.com/stock-share-price/Dichloromethane/500089/
A7: 500112 | B7: State Bank Of India | G7: https://www.bseindia.com/stock-share-price/State-Bank-Of-India/500112/
A8: 500128 | B8: Electrosteel Castings Ltd | G8: https://www.bseindia.com/stock-share-price/Electrosteel-Castings-Ltd/500128/
A9: 500143 | B9: GTL Ltd | G9: https://www.bseindia.com/stock-share-price/GTL-Ltd/500143/
A10: 500147 | B10: Usha Martin Ltd | G10: https://www.bseindia.com/stock-share-price/Usha-Martin-Ltd/500147/
A11: 500170 | B11: National Chemicals | G11: https://www.bseindia.com/stock-share-price/National-Chemicals/500170/
A12: 500182 | B12: Hero MotoCorp Ltd | G12: https://www.bseindia.com/stock-share-price/Hero-MotoCorp-Ltd/500182/
A13: 500184 | B13: Himadri Speciality Chemical Ltd | G13: https://www.bseindia.com/stock-share-price/Himadri-Speciality-Chemical-Ltd/500184/
... A222: 518017 | B222: Bedmutha Industries Ltd | G222: https://www.bseindia.com/stock-share-price/Bedmutha-Industries-Ltd/518017/

Sheet PE Band DETAIL v8
A1: Sr No | B1: BSE Code | C1: Company Name | D1: Calendar Year | E1: CMP TODAY All Years | F1: EPS (Rs) | G1: EPS Source | H1: Year High | I1: Year Low | J1: High PE Formula | K1: Low PE Formula | L1: Confidence Flag | M1: PE High | N1: PE Low | O1: BSE_CMP_Official_LIVE | P1: BSE_52W_High_Official | Q1: BSE_52W_Low_Official | R1: CMP_Match_Status | S1: Final_CMP_AutoCorrected | T1: Last_Verified_IST
A2: 4 | B2: 500008 | C2: Amara Raja Energy & Mobility Ltd | D2: 2015 | E2: 874.45001 | G2: Consolidated first (v4) – needs verification for flagged rows | H2: 1132 | I2: 778 | L2: INCOMPLETE | O2: 882.5 | P2: 1057.85 | Q2: 670 | R2: VERIFIED_OK | S2: 882.5 | T2: 30-07-2026 09:42 IST
A3: 4 | B3: 500008 | C3: Amara Raja Energy & Mobility Ltd | D3: 2016 | E3: 874.45001 | G3: Consolidated first (v4) – needs verification for flagged rows | H3: 1077 | I3: 773.05 | L3: INCOMPLETE | O3: 882.5 | P3: 1057.85 | Q3: 670 | R3: VERIFIED_OK | S3: 882.5 | T3: 30-07-2026 09:42 IST
A4: 4 | B4: 500008 | C4: Amara Raja Energy & Mobility Ltd | D4: 2017 | E4: 874.45001 | G4: Consolidated first (v4) – needs verification for flagged rows | H4: 954.54999 | I4: 665.45001 | L4: INCOMPLETE | O4: 882.5 | P4: 1057.85 | Q4: 670 | R4: VERIFIED_OK | S4: 882.5 | T4: 30-07-2026 09:42 IST
A5: 4 | B5: 500008 | C5: Amara Raja Energy & Mobility Ltd | D5: 2018 | E5: 874.45001 | G5: Consolidated first (v4) – needs verification for flagged rows | H5: 907.75 | I5: 670.65002 | L5: INCOMPLETE | O5: 882.5 | P5: 1057.85 | Q5: 670 | R5: VERIFIED_OK | S5: 882.5 | T5: 30-07-2026 09:42 IST
A6: 4 | B6: 500008 | C6: Amara Raja Energy & Mobility Ltd | D6: 2019 | E6: 874.45001 | F6: 28.29 | G6: Consolidated first (v4) – needs verification for flagged rows | H6: 796 | I6: 572.59998 | L6: OK | M6: 28.14 | N6: 20.24 | O6: 882.5 | P6: 1057.85 | Q6: 670 | R6: VERIFIED_OK | S6: 882.5 | T6: 30-07-2026 09:42 IST
A7: 4 | B7: 500008 | C7: Amara Raja Energy & Mobility Ltd | D7: 2020 | E7: 874.45001 | F7: 38.69 | G7: Consolidated first (v4) – needs verification for flagged rows | H7: 963.95001 | I7: 350.25 | L7: OK | M7: 24.91 | N7: 9.05 | O7: 882.5 | P7: 1057.85 | Q7: 670 | R7: VERIFIED_OK | S7: 882.5 | T7: 30-07-2026 09:42 IST
A8: 4 | B8: 500008 | C8: Amara Raja Energy & Mobility Ltd | D8: 2021 | E8: 874.45001 | F8: 37.87 | G8: Consolidated first (v4) – needs verification for flagged rows | H8: 1025 | I8: 584.45001 | L8: OK | M8: 27.07 | N8: 15.43 | O8: 882.5 | P8: 1057.85 | Q8: 670 | R8: VERIFIED_OK | S8: 882.5 | T8: 30-07-2026 09:42 IST
A9: 4 | B9: 500008 | C9: Amara Raja Energy & Mobility Ltd | D9: 2022 | E9: 874.45001 | F9: 30.01 | G9: Consolidated first (v4) – needs verification for flagged rows | H9: 669.95001 | I9: 445.39999 | L9: OK | M9: 22.32 | N9: 14.84 | O9: 882.5 | P9: 1057.85 | Q9: 670 | R9: VERIFIED_OK | S9: 882.5 | T9: 30-07-2026 09:42 IST
A10: 4 | B10: 500008 | C10: Amara Raja Energy & Mobility Ltd | D10: 2023 | E10: 874.45001 | F10: 42.79 | G10: Consolidated first (v4) – needs verification for flagged rows | H10: 831.25 | I10: 546.54999 | L10: OK | M10: 19.43 | N10: 12.77 | O10: 882.5 | P10: 1057.85 | Q10: 670 | R10: VERIFIED_OK | S10: 882.5 | T10: 30-07-2026 09:42 IST
A11: 4 | B11: 500008 | C11: Amara Raja Energy & Mobility Ltd | D11: 2024 | E11: 874.45001 | F11: 51.05 | G11: Consolidated first (v4) – needs verification for flagged rows | H11: 1774.9 | I11: 737.65002 | L11: OK | M11: 34.77 | N11: 14.45 | O11: 882.5 | P11: 1057.85 | Q11: 670 | R11: VERIFIED_OK | S11: 882.5 | T11: 30-07-2026 09:42 IST
A12: 4 | B12: 500008 | C12: Amara Raja Energy & Mobility Ltd | D12: 2025 | E12: 874.45001 | F12: 51.61 | G12: Consolidated first (v4) – needs verification for flagged rows | H12: 1220 | I12: 805.04999 | L12: OK | M12: 23.64 | N12: 15.6 | O12: 882.5 | P12: 1057.85 | Q12: 670 | R12: VERIFIED_OK | S12: 882.5 | T12: 30-07-2026 09:42 IST
A13: 4 | B13: 500008 | C13: Amara Raja Energy & Mobility Ltd | D13: 2026 | E13: 874.45001 | F13: 48.94 | G13: Consolidated first (v4) – needs verification for flagged rows | H13: 957.45001 | I13: 671.45001 | L13: OK | M13: 19.56 | N13: 13.72 | O13: 882.5 | P13: 1057.85 | Q13: 670 | R13: VERIFIED_OK | S13: 882.5 | T13: 30-07-2026 09:42 IST
A14: 6 | B14: 500034 | C14: Bajaj Finance Ltd | D14: 2015 | E14: 1055.7 | F14: 1.79 | G14: Consolidated first (v4) – needs verification for flagged rows | H14: 60.439999 | I14: 33.945999 | L14: OK | M14: 33.77 | N14: 18.96 | O14: 1054.8 | P14: 1102.5 | Q14: 787.9 | R14: VERIFIED_OK | S14: 1054.8 | T14: 30-07-2026 09:42 IST
A15: 6 | B15: 500034 | C15: Bajaj Finance Ltd | D15: 2016 | E15: 1055.7 | F15: 2.37 | G15: Consolidated first (v4) – needs verification for flagged rows | H15: 118 | I15: 53.5 | L15: OK | M15: 49.79 | N15: 22.57 | O15: 1054.8 | P15: 1102.5 | Q15: 787.9 | R15: VERIFIED_OK | S15: 1054.8 | T15: 30-07-2026 09:42 IST
A16: 6 | B16: 500034 | C16: Bajaj Finance Ltd | D16: 2017 | E16: 1055.7 | F16: 3.34 | G16: Consolidated first (v4) – needs verification for flagged rows | H16: 198.89999 | I16: 86 | L16: OK | M16: 59.55 | N16: 25.75 | O16: 1054.8 | P16: 1102.5 | Q16: 787.9 | R16: VERIFIED_OK | S16: 1054.8 | T16: 30-07-2026 09:42 IST
A17: 6 | B17: 500034 | C17: Bajaj Finance Ltd | D17: 2018 | E17: 1055.7 | F17: 4.32 | G17: Consolidated first (v4) – needs verification for flagged rows | H17: 299.51001 | I17: 151.44 | L17: OK | M17: 69.33 | N17: 35.06 | O17: 1054.8 | P17: 1102.5 | Q17: 787.9 | R17: VERIFIED_OK | S17: 1054.8 | T17: 30-07-2026 09:42 IST
... A32: 10 | B32: 500055 | C32: Bombay Dyeing | D32: 2021 | E32: 85.550003 | F32: -0.48 | G32: Consolidated first (v4) – needs verification for flagged rows | H32: 109.6 | I32: 37.400002 | L32: INCOMPLETE | M32: -228.33 | N32: -77.92 | O32: 1776.8 | P32: 2110 | Q32: 1322.5 | R32: MISMATCH_NEEDS_CORRECTION | S32: 1776.8 | T32: 30-07-2026 09:42 IST
A33: 11 | B33: 500059 | C33: Birla Power Solutions Ltd | D33: 2015 | E33: 4.0500002 | F33: -216.28 | G33: Consolidated first (v4) – needs verification for flagged rows | H33: 120.8 | I33: 69 | L33: UNVERIFIED – negative EPS | M33: -0.56 | N33: -0.32 | O33: =IFERROR(VLOOKUP(B33,BSE_500_LIVE!A:E,3,FALSE),"") | P33: =IFERROR(VLOOKUP(B33,BSE_500_LIVE!A:E,4,FALSE),"") | Q33: =IFERROR(VLOOKUP(B33,BSE_500_LIVE!A:E,5,FALSE),"") | R33: =IF(OR(E33="",O33=""),"PENDING_FETCH",IF(ABS(E33-O33)/E33>0.005,"MISMATCH_NEEDS_CORRECTION","VERIFIED_OK")) | S33: =IF(O33<>"",O33,E33) | T33: =IFERROR(VLOOKUP(B33,BSE_500_LIVE!A:F,6,FALSE),"")
A34: 11 | B34: 500059 | C34: Birla Power Solutions Ltd | D34: 2016 | E34: 4.0500002 | F34: -140.85 | G34: Consolidated first (v4) – needs verification for flagged rows | H34: 120.9 | I34: 50 | L34: UNVERIFIED – negative EPS | M34: -0.86 | N34: -0.35 | O34: =IFERROR(VLOOKUP(B34,BSE_500_LIVE!A:E,3,FALSE),"") | P34: =IFERROR(VLOOKUP(B34,BSE_500_LIVE!A:E,4,FALSE),"") | Q34: =IFERROR(VLOOKUP(B34,BSE_500_LIVE!A:E,5,FALSE),"") | R34: =IF(OR(E34="",O34=""),"PENDING_FETCH",IF(ABS(E34-O34)/E34>0.005,"MISMATCH_NEEDS_CORRECTION","VERIFIED_OK")) | S34: =IF(O34<>"",O34,E34) | T34: =IFERROR(VLOOKUP(B34,BSE_500_LIVE!A:F,6,FALSE),"")
A35: 11 | B35: 500059 | C35: Birla Power Solutions Ltd | D35: 2017 | E35: 4.0500002 | F35: -146.95 | G35: Consolidated first (v4) – needs verification for flagged rows | H35: 149.39999 | I35: 67.050003 | L35: UNVERIFIED – negative EPS | M35: -1.02 | N35: -0.46 | O35: =IFERROR(VLOOKUP(B35,BSE_500_LIVE!A:E,3,FALSE),"") | P35: =IFERROR(VLOOKUP(B35,BSE_500_LIVE!A:E,4,FALSE),"") | Q35: =IFERROR(VLOOKUP(B35,BSE_500_LIVE!A:E,5,FALSE),"") | R35: =IF(OR(E35="",O35=""),"PENDING_FETCH",IF(ABS(E35-O35)/E35>0.005,"MISMATCH_NEEDS_CORRECTION","VERIFIED_OK")) | S35: =IF(O35<>"",O35,E35) | T35: =IFERROR(VLOOKUP(B35,BSE_500_LIVE!A:F,6,FALSE),"")
A36: 11 | B36: 500059 | C36: Birla Power Solutions Ltd | D36: 2018 | E36: 4.0500002 | F36: 8.33 | G36: Consolidated first (v4) – needs verification for flagged rows | H36: 152.8 | I36: 64.199997 | L36: OK | M36: 18.34 | N36: 7.71 | O36: =IFERROR(VLOOKUP(B36,BSE_500_LIVE!A:E,3,FALSE),"") | P36: =IFERROR(VLOOKUP(B36,BSE_500_LIVE!A:E,4,FALSE),"") | Q36: =IFERROR(VLOOKUP(B36,BSE_500_LIVE!A:E,5,FALSE),"") | R36: =IF(OR(E36="",O36=""),"PENDING_FETCH",IF(ABS(E36-O36)/E36>0.005,"MISMATCH_NEEDS_CORRECTION","VERIFIED_OK")) | S36: =IF(O36<>"",O36,E36) | T36: =IFERROR(VLOOKUP(B36,BSE_500_LIVE!A:F,6,FALSE),"")
A37: 11 | B37: 500059 | C37: Birla Power Solutions Ltd | D37: 2019 | E37: 4.0500002 | F37: 347.49 | G37: Consolidated first (v4) – needs verification for flagged rows | H37: 75 | I37: 5.4299998 | L37: OK | M37: 0.22 | N37: 0.02 | O37: =IFERROR(VLOOKUP(B37,BSE_500_LIVE!A:E,3,FALSE),"") | P37: =IFERROR(VLOOKUP(B37,BSE_500_LIVE!A:E,4,FALSE),"") | Q37: =IFERROR(VLOOKUP(B37,BSE_500_LIVE!A:E,5,FALSE),"") | R37: =IF(OR(E37="",O37=""),"PENDING_FETCH",IF(ABS(E37-O37)/E37>0.005,"MISMATCH_NEEDS_CORRECTION","VERIFIED_OK")) | S37: =IF(O37<>"",O37,E37) | T37: =IFERROR(VLOOKUP(B37,BSE_500_LIVE!A:F,6,FALSE),"")
A38: 11 | B38: 500059 | C38: Birla Power Solutions Ltd | D38: 2020 | E38: 4.0500002 | F38: -395.75 | G38: Consolidated first (v4) – needs verification for flagged rows | H38: 8.6499996 | I38: 5.4699998 | L38: UNVERIFIED – negative EPS | M38: -0.02 | N38: -0.01 | O38: =IFERROR(VLOOKUP(B38,BSE_500_LIVE!A:E,3,FALSE),"") | P38: =IFERROR(VLOOKUP(B38,BSE_500_LIVE!A:E,4,FALSE),"") | Q38: =IFERROR(VLOOKUP(B38,BSE_500_LIVE!A:E,5,FALSE),"") | R38: =IF(OR(E38="",O38=""),"PENDING_FETCH",IF(ABS(E38-O38)/E38>0.005,"MISMATCH_NEEDS_CORRECTION","VERIFIED_OK")) | S38: =IF(O38<>"",O38,E38) | T38: =IFERROR(VLOOKUP(B38,BSE_500_LIVE!A:F,6,FALSE),"")
A39: 11 | B39: 500059 | C39: Birla Power Solutions Ltd | D39: 2021 | E39: 4.0500002 | F39: 93.36 | G39: Consolidated first (v4) – needs verification for flagged rows | H39: 5.5 | I39: 5.5 | L39: OK | M39: 0.06 | N39: 0.06 | O39: =IFERROR(VLOOKUP(B39,BSE_500_LIVE!A:E,3,FALSE),"") | P39: =IFERROR(VLOOKUP(B39,BSE_500_LIVE!A:E,4,FALSE),"") | Q39: =IFERROR(VLOOKUP(B39,BSE_500_LIVE!A:E,5,FALSE),"") | R39: =IF(OR(E39="",O39=""),"PENDING_FETCH",IF(ABS(E39-O39)/E39>0.005,"MISMATCH_NEEDS_CORRECTION","VERIFIED_OK")) | S39: =IF(O39<>"",O39,E39) | T39: =IFERROR(VLOOKUP(B39,BSE_500_LIVE!A:F,6,FALSE),"")
A40: 11 | B40: 500059 | C40: Birla Power Solutions Ltd | D40: 2022 | E40: 4.0500002 | F40: 56.89 | G40: Consolidated first (v4) – needs verification for flagged rows | H40: 5.5 | I40: 5.5 | L40: OK | M40: 0.1 | N40: 0.1 | O40: =IFERROR(VLOOKUP(B40,BSE_500_LIVE!A:E,3,FALSE),"") | P40: =IFERROR(VLOOKUP(B40,BSE_500_LIVE!A:E,4,FALSE),"") | Q40: =IFERROR(VLOOKUP(B40,BSE_500_LIVE!A:E,5,FALSE),"") | R40: =IF(OR(E40="",O40=""),"PENDING_FETCH",IF(ABS(E40-O40)/E40>0.005,"MISMATCH_NEEDS_CORRECTION","VERIFIED_OK")) | S40: =IF(O40<>"",O40,E40) | T40: =IFERROR(VLOOKUP(B40,BSE_500_LIVE!A:F,6,FALSE),"")
A41: 11 | B41: 500059 | C41: Birla Power Solutions Ltd | D41: 2023 | E41: 4.0500002 | F41: -48.05 | G41: Consolidated first (v4) – needs verification for flagged rows | H41: 36.490002 | I41: 5.5 | L41: UNVERIFIED – negative EPS | M41: -0.76 | N41: -0.11 | O41: =IFERROR(VLOOKUP(B41,BSE_500_LIVE!A:E,3,FALSE),"") | P41: =IFERROR(VLOOKUP(B41,BSE_500_LIVE!A:E,4,FALSE),"") | Q41: =IFERROR(VLOOKUP(B41,BSE_500_LIVE!A:E,5,FALSE),"") | R41: =IF(OR(E41="",O41=""),"PENDING_FETCH",IF(ABS(E41-O41)/E41>0.005,"MISMATCH_NEEDS_CORRECTION","VERIFIED_OK")) | S41: =IF(O41<>"",O41,E41) | T41: =IFERROR(VLOOKUP(B41,BSE_500_LIVE!A:F,6,FALSE),"")
A42: 11 | B42: 500059 | C42: Birla Power Solutions Ltd | D42: 2024 | E42: 4.0500002 | F42: -2.28 | G42: Consolidated first (v4) – needs verification for flagged rows | H42: 22.1 | I42: 13.22 | L42: UNVERIFIED – negative EPS | M42: -9.69 | N42: -5.8 | O42: =IFERROR(VLOOKUP(B42,BSE_500_LIVE!A:E,3,FALSE),"") | P42: =IFERROR(VLOOKUP(B42,BSE_500_LIVE!A:E,4,FALSE),"") | Q42: =IFERROR(VLOOKUP(B42,BSE_500_LIVE!A:E,5,FALSE),"") | R42: =IF(OR(E42="",O42=""),"PENDING_FETCH",IF(ABS(E42-O42)/E42>0.005,"MISMATCH_NEEDS_CORRECTION","VERIFIED_OK")) | S42: =IF(O42<>"",O42,E42) | T42: =IFERROR(VLOOKUP(B42,BSE_500_LIVE!A:F,6,FALSE),"")
A43: 11 | B43: 500059 | C43: Birla Power Solutions Ltd | D43: 2025 | E43: 4.0500002 | F43: 2.18 | G43: Consolidated first (v4) – needs verification for flagged rows | H43: 23.559999 | I43: 6.6599998 | L43: OK | M43: 10.81 | N43: 3.06 | O43: =IFERROR(VLOOKUP(B43,BSE_500_LIVE!A:E,3,FALSE),"") | P43: =IFERROR(VLOOKUP(B43,BSE_500_LIVE!A:E,4,FALSE),"") | Q43: =IFERROR(VLOOKUP(B43,BSE_500_LIVE!A:E,5,FALSE),"") | R43: =IF(OR(E43="",O43=""),"PENDING_FETCH",IF(ABS(E43-O43)/E43>0.005,"MISMATCH_NEEDS_CORRECTION","VERIFIED_OK")) | S43: =IF(O43<>"",O43,E43) | T43: =IFERROR(VLOOKUP(B43,BSE_500_LIVE!A:F,6,FALSE),"")
A44: 11 | B44: 500059 | C44: Birla Power Solutions Ltd | D44: 2026 | E44: 4.0500002 | F44: -0.01 | G44: Consolidated first (v4) – needs verification for flagged rows | H44: 7.6500001 | I44: 3.8199999 | L44: UNVERIFIED – negative EPS | M44: -765 | N44: -382 | O44: =IFERROR(VLOOKUP(B44,BSE_500_LIVE!A:E,3,FALSE),"") | P44: =IFERROR(VLOOKUP(B44,BSE_500_LIVE!A:E,4,FALSE),"") | Q44: =IFERROR(VLOOKUP(B44,BSE_500_LIVE!A:E,5,FALSE),"") | R44: =IF(OR(E44="",O44=""),"PENDING_FETCH",IF(ABS(E44-O44)/E44>0.005,"MISMATCH_NEEDS_CORRECTION","VERIFIED_OK")) | S44: =IF(O44<>"",O44,E44) | T44: =IFERROR(VLOOKUP(B44,BSE_500_LIVE!A:F,6,FALSE),"")
A45: 13 | B45: 500089 | C45: Dichloromethane | D45: 2015 | E45: 512.90002 | G45: Consolidated first (v4) – needs verification for flagged rows | H45: 746.75 | L45: INCOMPLETE | O45: =IFERROR(VLOOKUP(B45,BSE_500_LIVE!A:E,3,FALSE),"") | P45: =IFERROR(VLOOKUP(B45,BSE_500_LIVE!A:E,4,FALSE),"") | Q45: =IFERROR(VLOOKUP(B45,BSE_500_LIVE!A:E,5,FALSE),"") | R45: =IF(OR(E45="",O45=""),"PENDING_FETCH",IF(ABS(E45-O45)/E45>0.005,"MISMATCH_NEEDS_CORRECTION","VERIFIED_OK")) | S45: =IF(O45<>"",O45,E45) | T45: =IFERROR(VLOOKUP(B45,BSE_500_LIVE!A:F,6,FALSE),"")
A46: 13 | B46: 500089 | C46: Dichloromethane | D46: 2016 | E46: 512.90002 | G46: Consolidated first (v4) – needs verification for flagged rows | H46: 745.75 | I46: 443 | L46: INCOMPLETE | O46: =IFERROR(VLOOKUP(B46,BSE_500_LIVE!A:E,3,FALSE),"") | P46: =IFERROR(VLOOKUP(B46,BSE_500_LIVE!A:E,4,FALSE),"") | Q46: =IFERROR(VLOOKUP(B46,BSE_500_LIVE!A:E,5,FALSE),"") | R46: =IF(OR(E46="",O46=""),"PENDING_FETCH",IF(ABS(E46-O46)/E46>0.005,"MISMATCH_NEEDS_CORRECTION","VERIFIED_OK")) | S46: =IF(O46<>"",O46,E46) | T46: =IFERROR(VLOOKUP(B46,BSE_500_LIVE!A:F,6,FALSE),"")
A47: 13 | B47: 500089 | C47: Dichloromethane | D47: 2017 | E47: 512.90002 | G47: Consolidated first (v4) – needs verification for flagged rows | H47: 605 | I47: 432.64999 | L47: INCOMPLETE | O47: =IFERROR(VLOOKUP(B47,BSE_500_LIVE!A:E,3,FALSE),"") | P47: =IFERROR(VLOOKUP(B47,BSE_500_LIVE!A:E,4,FALSE),"") | Q47: =IFERROR(VLOOKUP(B47,BSE_500_LIVE!A:E,5,FALSE),"") | R47: =IF(OR(E47="",O47=""),"PENDING_FETCH",IF(ABS(E47-O47)/E47>0.005,"MISMATCH_NEEDS_CORRECTION","VERIFIED_OK")) | S47: =IF(O47<>"",O47,E47) | T47: =IFERROR(VLOOKUP(B47,BSE_500_LIVE!A:F,6,FALSE),"")
A48: 13 | B48: 500089 | C48: Dichloromethane | D48: 2018 | E48: 512.90002 | G48: Consolidated first (v4) – needs verification for flagged rows | H48: 635 | I48: 332 | L48: INCOMPLETE | O48: =IFERROR(VLOOKUP(B48,BSE_500_LIVE!A:E,3,FALSE),"") | P48: =IFERROR(VLOOKUP(B48,BSE_500_LIVE!A:E,4,FALSE),"") | Q48: =IFERROR(VLOOKUP(B48,BSE_500_LIVE!A:E,5,FALSE),"") | R48: =IF(OR(E48="",O48=""),"PENDING_FETCH",IF(ABS(E48-O48)/E48>0.005,"MISMATCH_NEEDS_CORRECTION","VERIFIED_OK")) | S48: =IF(O48<>"",O48,E48) | T48: =IFERROR(VLOOKUP(B48,BSE_500_LIVE!A:F,6,FALSE),"")
A49: 13 | B49: 500089 | C49: Dichloromethane | D49: 2019 | E49: 512.90002 | G49: Consolidated first (v4) – needs verification for flagged rows | H49: 424 | I49: 294.10001 | L49: INCOMPLETE | O49: =IFERROR(VLOOKUP(B49,BSE_500_LIVE!A:E,3,FALSE),"") | P49: =IFERROR(VLOOKUP(B49,BSE_500_LIVE!A:E,4,FALSE),"") | Q49: =IFERROR(VLOOKUP(B49,BSE_500_LIVE!A:E,5,FALSE),"") | R49: =IF(OR(E49="",O49=""),"PENDING_FETCH",IF(ABS(E49-O49)/E49>0.005,"MISMATCH_NEEDS_CORRECTION","VERIFIED_OK")) | S49: =IF(O49<>"",O49,E49) | T49: =IFERROR(VLOOKUP(B49,BSE_500_LIVE!A:F,6,FALSE),"")
A50: 13 | B50: 500089 | C50: Dichloromethane | D50: 2020 | E50: 512.90002 | G50: Consolidated first (v4) – needs verification for flagged rows | H50: 450 | I50: 242 | L50: INCOMPLETE | O50: =IFERROR(VLOOKUP(B50,BSE_500_LIVE!A:E,3,FALSE),"") | P50: =IFERROR(VLOOKUP(B50,BSE_500_LIVE!A:E,4,FALSE),"") | Q50: =IFERROR(VLOOKUP(B50,BSE_500_LIVE!A:E,5,FALSE),"") | R50: =IF(OR(E50="",O50=""),"PENDING_FETCH",IF(ABS(E50-O50)/E50>0.005,"MISMATCH_NEEDS_CORRECTION","VERIFIED_OK")) | S50: =IF(O50<>"",O50,E50) | T50: =IFERROR(VLOOKUP(B50,BSE_500_LIVE!A:F,6,FALSE),"")
A51: 13 | B51: 500089 | C51: Dichloromethane | D51: 2021 | E51: 512.90002 | G51: Consolidated first (v4) – needs verification for flagged rows | H51: 549 | I51: 367.5 | L51: INCOMPLETE | O51: =IFERROR(VLOOKUP(B51,BSE_500_LIVE!A:E,3,FALSE),"") | P51: =IFERROR(VLOOKUP(B51,BSE_500_LIVE!A:E,4,FALSE),"") | Q51: =IFERROR(VLOOKUP(B51,BSE_500_LIVE!A:E,5,FALSE),"") | R51: =IF(OR(E51="",O51=""),"PENDING_FETCH",IF(ABS(E51-O51)/E51>0.005,"MISMATCH_NEEDS_CORRECTION","VERIFIED_OK")) | S51: =IF(O51<>"",O51,E51) | T51: =IFERROR(VLOOKUP(B51,BSE_500_LIVE!A:F,6,FALSE),"")
A52: 13 | B52: 500089 | C52: Dichloromethane | D52: 2022 | E52: 512.90002 | G52: Consolidated first (v4) – needs verification for flagged rows | H52: 493.85001 | I52: 321 | L52: INCOMPLETE | O52: =IFERROR(VLOOKUP(B52,BSE_500_LIVE!A:E,3,FALSE),"") | P52: =IFERROR(VLOOKUP(B52,BSE_500_LIVE!A:E,4,FALSE),"") | Q52: =IFERROR(VLOOKUP(B52,BSE_500_LIVE!A:E,5,FALSE),"") | R52: =IF(OR(E52="",O52=""),"PENDING_FETCH",IF(ABS(E52-O52)/E52>0.005,"MISMATCH_NEEDS_CORRECTION","VERIFIED_OK")) | S52: =IF(O52<>"",O52,E52) | T52: =IFERROR(VLOOKUP(B52,BSE_500_LIVE!A:F,6,FALSE),"")
A53: 13 | B53: 500089 | C53: Dichloromethane | D53: 2023 | E53: 512.90002 | G53: Consolidated first (v4) – needs verification for flagged rows | H53: 544 | I53: 366 | L53: INCOMPLETE | O53: =IFERROR(VLOOKUP(B53,BSE_500_LIVE!A:E,3,FALSE),"") | P53: =IFERROR(VLOOKUP(B53,BSE_500_LIVE!A:E,4,FALSE),"") | Q53: =IFERROR(VLOOKUP(B53,BSE_500_LIVE!A:E,5,FALSE),"") | R53: =IF(OR(E53="",O53=""),"PENDING_FETCH",IF(ABS(E53-O53)/E53>0.005,"MISMATCH_NEEDS_CORRECTION","VERIFIED_OK")) | S53: =IF(O53<>"",O53,E53) | T53: =IFERROR(VLOOKUP(B53,BSE_500_LIVE!A:F,6,FALSE),"")
A54: 13 | B54: 500089 | C54: Dichloromethane | D54: 2024 | E54: 512.90002 | G54: Consolidated first (v4) – needs verification for flagged rows | H54: 833 | I54: 414.20001 | L54: INCOMPLETE | O54: =IFERROR(VLOOKUP(B54,BSE_500_LIVE!A:E,3,FALSE),"") | P54: =IFERROR(VLOOKUP(B54,BSE_500_LIVE!A:E,4,FALSE),"") | Q54: =IFERROR(VLOOKUP(B54,BSE_500_LIVE!A:E,5,FALSE),"") | R54: =IF(OR(E54="",O54=""),"PENDING_FETCH",IF(ABS(E54-O54)/E54>0.005,"MISMATCH_NEEDS_CORRECTION","VERIFIED_OK")) | S54: =IF(O54<>"",O54,E54) | T54: =IFERROR(VLOOKUP(B54,BSE_500_LIVE!A:F,6,FALSE),"")
...

Sheet LARGE CAP CORRECTIONS
A1: BSE Code | B1: Company | C1: Year | D1: Old EPS in file | E1: Corrected EPS | F1: Old PE | G1: New PE | H1: Source | I1: Status
A2: 500112 | B2: State Bank of India | C2: 2017 | D2: 0.3 | E2: 13.15 | F2: 1172 | G2: 26.8 | H2: Annual Report FY17 net profit 10,484cr / 797cr shares =13.15 – scribd table【3435303340785564242†L20-L23】 | I2: VERIFIED
A3: 500825 | B3: Britannia Industries | C3: 2017 | D3: -0.48 | E3: 36.8 | F3: -275 | G3: 95 | H3: Moneycontrol research Y/E March 2017 EPS 36.8【5364693404258100898†L13-L16】 | I3: VERIFIED
A4: 500520 | B4: Mahindra & Mahindra | C4: 2020 | D4: 1.02 | E4: 11.2 | F4: 749 | G4: 67 | H4: ICICI Direct FY20 EPS 11.2【5535724775168940871†L9-L12】 | I4: VERIFIED

Sheet VERIFICATION_LOG
A1: Timestamp IST | B1: BSE Code | C1: Company | D1: Calendar Year | E1: Field | F1: Excel Old CMP | G1: BSE Official CMP | H1: Difference % | I1: Action | J1: BSE Proof URL | K1: EPS Note
A2: =NOW() | B2: Example 500325 | C2: Reliance | D2: 2026 | E2: CMP | F2: 1500 | G2: 1520 | H2: =ABS(F2-G2)/F2*100 | I2: AUTO-CORRECTED | J2: https://www.bseindia.com/stock-share-price/reliance/500325/ | K2: EPS historical needs annual report

Sheet HOW_TO_USE_FINAL
A1: FINAL MERGED MASTER - HOW TO USE - Auto Update 10PM IST
A3: This file is your FINAL ready file - 2479 rows (2015-2026) + LIVE BSE columns
A4: Columns E = your old CMP TODAY All Years (kept as is)
A5: Columns O-T = new LIVE official columns that auto-fill from BSE_500_LIVE sheet via VLOOKUP
A7: STEPS TO MAKE IT LIVE:
A8: 1. Go to BSE_500_LIVE sheet - select A1:G222 - press Ctrl+T - name table as BSECodes
A9: 2. Data > Get Data > Blank Query > Advanced Editor > Paste M Code from previous file
A10: 3. Query will populate columns C,D,E in BSE_500_LIVE from BSE API
A11: 4. As soon as BSE_500_LIVE updates, ALL 2479 rows in PE Band DETAIL v8 auto-update via VLOOKUP formulas
A12: 5. For 10PM auto: Alt+F11 > paste VBA, save as .xlsm, schedule Task Scheduler to open at 9:59 PM
A14: WHAT GETS AUTO-CORRECTED:
A15: - Final_CMP_AutoCorrected = If BSE live exists, uses BSE official, else keeps your old
... A18: - EPS: Historical EPS (2015-2025) kept as is - BSE API only gives current TTM EPS, so only flagged
